Workbook

Sheet Base de donnée
AF4: del15 | AG4: 0.85 | AH4: =AG4 -> 0.85 | AI4: =AH4 -> 0.85 | AJ4: =AI4 -> 0.85 | AK4: =AJ4 -> 0.85 | AL4: =AK4 -> 0.85 | AM4: =AL4 -> 0.85 | AN4: =AM4 -> 0.85 | AO4: =AN4 -> 0.85 | ... AS4: =AR4 -> 0.85
X5: 1000000 | AF5: minima | AG5: 0.9 | AH5: =AG5 -> 0.9 | AI5: =AH5 -> 0.9 | AJ5: =AI5 -> 0.9 | AK5: =AJ5 -> 0.9 | AL5: =AK5 -> 0.9 | AM5: =AL5 -> 0.9 | AN5: =AM5 -> 0.9 | AO5: =AN5 -> 0.9 | ... AS5: =AR5 -> 0.9
X6: =IF(X5=1000,"milliers","millions") -> millions | AF6: appel traités | AG6: 0.9 | AH6: =AG6 -> 0.9 | AI6: =AH6 -> 0.9 | AJ6: =AI6 -> 0.9 | AK6: =AJ6 -> 0.9 | AL6: =AK6 -> 0.9 | AM6: =AL6 -> 0.9 | AN6: =AM6 -> 0.9 | AO6: =AN6 -> 0.9 | ... AS6: =AR6 -> 0.9
AF7: appel agents | AG7: 0.9 | AH7: =AG7 -> 0.9 | AI7: =AH7 -> 0.9 | AJ7: =AI7 -> 0.9 | AK7: =AJ7 -> 0.9 | AL7: =AK7 -> 0.9 | AM7: =AL7 -> 0.9 | AN7: =AM7 -> 0.9 | AO7: =AN7 -> 0.9 | ... AS7: =AR7 -> 0.9
AF8: visites 20 | AG8: 0.85 | AH8: =AG8 -> 0.85 | AI8: =AH8 -> 0.85 | AJ8: =AI8 -> 0.85 | AK8: =AJ8 -> 0.85 | AL8: =AK8 -> 0.85 | AM8: =AL8 -> 0.85 | AN8: =AM8 -> 0.85 | AO8: =AN8 -> 0.85 | ... AS8: =AR8 -> 0.85
AG10: Jan | AH10: Fev | AI10: Mars | AJ10: Avr | AK10: Mai | AL10: Juin | AM10: Juil | AN10: Août | AO10: Sept | AP10: Oct | AQ10: Nov | AR10: Dec | AS10: Cumul | AV10: 1 | AW10: Janvier
AV11: 2 | AW11: Fevrier
AV12: 3 | AW12: Mars
AD13: D | AE13: E | AF13: F | AG13: G | AH13: H | AI13: I | AJ13: J | AK13: K | AL13: L | AM13: M | AN13: N | AO13: O | AP13: P | AQ13: Q | AR13: R | AS13: S | AV13: 4 | AW13: Avril
D14: NUMORG | E14: annee | F14: _NAME_ | G14: 1 | H14: 2 | I14: 3 | J14: 4 | K14: 5 | L14: 6 | M14: 7 | N14: 8 | O14: 9 | P14: 10 | Q14: 11 | R14: 12 | S14: COL1 | W14: Rang | X14: NumOrg | Y14: Début | Z14: Fin | AD14: NUMORG | AE14: annee | AF14: _NAME_ | AG14: 1 | AH14: 2 | AI14: 3 | AJ14: 4 | AK14: 5 | AL14: 6 | AM14: 7 | AN14: 8 | AO14: 9 | AP14: 10 | AQ14: 11 | AR14: 12 | AS14: COL1 | AV14: 5 | AW14: Mai
D15: 000 | E15: 2013 | F15: VIS20_cc | S15: 0.86826409 | W15: 1 | X15: 000 | Y15: 15 | Z15: 68 | AC15: =VLOOKUP(tdb1_ems!C1,'Base de donnée'!W15:Z117,3) -> 69 | AD15: {=IF(INDIRECT(AD$13&$AC15)=0,NA(),INDIRECT(AD$13&$AC15))} -> 01a | AE15: {=IF(INDIRECT(AE$13&$AC15)=0,NA(),INDIRECT(AE$13&$AC15))} -> 2013 | AF15: {=IF(INDIRECT(AF$13&$AC15)=0,NA(),INDIRECT(AF$13&$AC15))} -> VIS20_cc | AG15: {=IF(INDIRECT(AG$13&$AC15)=0,NA(),INDIRECT(AG$13&$AC15))} -> #N/A | AH15: {=IF(INDIRECT(AH$13&$AC15)=0,NA(),INDIRECT(AH$13&$AC15))} -> #N/A | AI15: {=IF(INDIRECT(AI$13&$AC15)=0,NA(),INDIRECT(AI$13&$AC15))} -> #N/A | AJ15: {=IF(INDIRECT(AJ$13&$AC15)=0,NA(),INDIRECT(AJ$13&$AC15))} -> #N/A | AK15: {=IF(INDIRECT(AK$13&$AC15)=0,NA(),INDIRECT(AK$13&$AC15))} -> #N/A | ... AS15: {=IF(INDIRECT(AS$13&$AC15)=0,NA(),INDIRECT(AS$13&$AC15))} -> 0.83363363 | AV15: 6 | AW15: Juin
D16: 000 | E16: 2014 | F16: VIS20_cc | S16: 0.88626276 | W16: 2 | X16: 01a | Y16: =Z15+1 -> 69 | Z16: =Y16+(Z15-Y15) -> 122 | AC16: =AC15+1 -> 70 | AD16: {=IF(INDIRECT(AD$13&$AC16)=0,NA(),INDIRECT(AD$13&$AC16))} -> 01a | AE16: {=IF(INDIRECT(AE$13&$AC16)=0,NA(),INDIRECT(AE$13&$AC16))} -> 2014 | AF16: {=IF(INDIRECT(AF$13&$AC16)=0,NA(),INDIRECT(AF$13&$AC16))} -> VIS20_cc | AG16: {=IF(INDIRECT(AG$13&$AC16)=0,NA(),INDIRECT(AG$13&$AC16))} -> #N/A | AH16: {=IF(INDIRECT(AH$13&$AC16)=0,NA(),INDIRECT(AH$13&$AC16))} -> #N/A | AI16: {=IF(INDIRECT(AI$13&$AC16)=0,NA(),INDIRECT(AI$13&$AC16))} -> #N/A | AJ16: {=IF(INDIRECT(AJ$13&$AC16)=0,NA(),INDIRECT(AJ$13&$AC16))} -> #N/A | AK16: {=IF(INDIRECT(AK$13&$AC16)=0,NA(),INDIRECT(AK$13&$AC16))} -> #N/A | ... AS16: {=IF(INDIRECT(AS$13&$AC16)=0,NA(),INDIRECT(AS$13&$AC16))} -> 0.81313634 | AV16: 7 | AW16: Juillet
D17: 000 | E17: 2015 | F17: VIS20_cc | S17: 0.91326402 | W17: 3 | X17: 01b | Y17: =Z16+1 -> 123 | Z17: =Y17+(Z16-Y16) -> 176 | AC17: =AC16+1 -> 71 | AD17: {=IF(INDIRECT(AD$13&$AC17)=0,NA(),INDIRECT(AD$13&$AC17))} -> 01a | AE17: {=IF(INDIRECT(AE$13&$AC17)=0,NA(),INDIRECT(AE$13&$AC17))} -> 2015 | AF17: {=IF(INDIRECT(AF$13&$AC17)=0,NA(),INDIRECT(AF$13&$AC17))} -> VIS20_cc | AG17: {=IF(INDIRECT(AG$13&$AC17)=0,NA(),INDIRECT(AG$13&$AC17))} -> #N/A | AH17: {=IF(INDIRECT(AH$13&$AC17)=0,NA(),INDIRECT(AH$13&$AC17))} -> #N/A | AI17: {=IF(INDIRECT(AI$13&$AC17)=0,NA(),INDIRECT(AI$13&$AC17))} -> #N/A | AJ17: {=IF(INDIRECT(AJ$13&$AC17)=0,NA(),INDIRECT(AJ$13&$AC17))} -> #N/A | AK17: {=IF(INDIRECT(AK$13&$AC17)=0,NA(),INDIRECT(AK$13&$AC17))} -> #N/A | ... AS17: {=IF(INDIRECT(AS$13&$AC17)=0,NA(),INDIRECT(AS$13&$AC17))} -> 0.99590293 | AV17: 8 | AW17: Août
D18: 000 | E18: 2013 | F18: VIS20_mm | G18: 0.83870853 | H18: 0.83457651 | I18: 0.86192915 | J18: 0.87448044 | K18: 0.86620474 | L18: 0.90259832 | M18: 0.91205997 | N18: 0.90539301 | O18: 0.88406401 | P18: 0.89550736 | Q18: 0.8700318 | R18: 0.87931005 | U18: 1 | V18: Janvier | W18: 4 | X18: 01c | Y18: =Z17+1 -> 177 | Z18: =Y18+(Z17-Y17) -> 230 | AC18: =AC17+1 -> 72 | AD18: {=IF(INDIRECT(AD$13&$AC18)=0,NA(),INDIRECT(AD$13&$AC18))} -> 01a | AE18: {=IF(INDIRECT(AE$13&$AC18)=0,NA(),INDIRECT(AE$13&$AC18))} -> 2013 | AF18: {=IF(INDIRECT(AF$13&$AC18)=0,NA(),INDIRECT(AF$13&$AC18))} -> VIS20_mm | AG18: {=IF(INDIRECT(AG$13&$AC18)=0,NA(),INDIRECT(AG$13&$AC18))} -> 0.763094 | AH18: {=IF(INDIRECT(AH$13&$AC18)=0,NA(),INDIRECT(AH$13&$AC18))} -> 0.82007056 | AI18: {=IF(INDIRECT(AI$13&$AC18)=0,NA(),INDIRECT(AI$13&$AC18))} -> 0.82967255 | AJ18: {=IF(INDIRECT(AJ$13&$AC18)=0,NA(),INDIRECT(AJ$13&$AC18))} -> 0.82321942 | AK18: {=IF(INDIRECT(AK$13&$AC18)=0,NA(),INDIRECT(AK$13&$AC18))} -> 0.82439901 | ... AS18: {=IF(INDIRECT(AS$13&$AC18)=0,NA(),INDIRECT(AS$13&$AC18))} -> #N/A | AV18: 9 | AW18: Septembre
D19: 000 | E19: 2014 | F19: VIS20_mm | G19: 0.8534 | H19: 0.86229021 | I19: 0.87654247 | J19: 0.90438853 | K19: 0.89862291 | L19: 0.9096216 | M19: 0.91786177 | N19: 0.91594487 | O19: 0.89933997 | P19: 0.90851699 | Q19: 0.89989706 | R19: 0.90270635 | W19: 5 | X19: 01d | Y19: =Z18+1 -> 231 | Z19: =Y19+(Z18-Y18) -> 284 | AC19: =AC18+1 -> 73 | AD19: {=IF(INDIRECT(AD$13&$AC19)=0,NA(),INDIRECT(AD$13&$AC19))} -> 01a | AE19: {=IF(INDIRECT(AE$13&$AC19)=0,NA(),INDIRECT(AE$13&$AC19))} -> 2014 | AF19: {=IF(INDIRECT(AF$13&$AC19)=0,NA(),INDIRECT(AF$13&$AC19))} -> VIS20_mm | AG19: {=IF(INDIRECT(AG$13&$AC19)=0,NA(),INDIRECT(AG$13&$AC19))} -> 0.72525016 | AH19: {=IF(INDIRECT(AH$13&$AC19)=0,NA(),INDIRECT(AH$13&$AC19))} -> 0.76704055 | AI19: {=IF(INDIRECT(AI$13&$AC19)=0,NA(),INDIRECT(AI$13&$AC19))} -> 0.76099454 | AJ19: {=IF(INDIRECT(AJ$13&$AC19)=0,NA(),INDIRECT(AJ$13&$AC19))} -> 0.81193798 | AK19: {=IF(INDIRECT(AK$13&$AC19)=0,NA(),INDIRECT(AK$13&$AC19))} -> 0.88894575 | ... AS19: {=IF(INDIRECT(AS$13&$AC19)=0,NA(),INDIRECT(AS$13&$AC19))} -> #N/A | AV19: 10 | AW19: Octobre
D20: 000 | E20: 2015 | F20: VIS20_mm | G20: 0.8883414 | H20: 0.89679391 | I20: 0.90097011 | J20: 0.92095796 | K20: 0.91328976 | L20: 0.94029241 | M20: 0.94343431 | W20: 6 | X20: 01e | Y20: =Z19+1 -> 285 | Z20: =Y20+(Z19-Y19) -> 338 | AC20: =AC19+1 -> 74 | AD20: {=IF(INDIRECT(AD$13&$AC20)=0,NA(),INDIRECT(AD$13&$AC20))} -> 01a | AE20: {=IF(INDIRECT(AE$13&$AC20)=0,NA(),INDIRECT(AE$13&$AC20))} -> 2015 | AF20: {=IF(INDIRECT(AF$13&$AC20)=0,NA(),INDIRECT(AF$13&$AC20))} -> VIS20_mm | AG20: {=IF(INDIRECT(AG$13&$AC20)=0,NA(),INDIRECT(AG$13&$AC20))} -> 0.99510726 | AH20: {=IF(INDIRECT(AH$13&$AC20)=0,NA(),INDIRECT(AH$13&$AC20))} -> 0.99567334 | AI20: {=IF(INDIRECT(AI$13&$AC20)=0,NA(),INDIRECT(AI$13&$AC20))} -> 0.99630802 | AJ20: {=IF(INDIRECT(AJ$13&$AC20)=0,NA(),INDIRECT(AJ$13&$AC20))} -> 0.99634592 | AK20: {=IF(INDIRECT(AK$13&$AC20)=0,NA(),INDIRECT(AK$13&$AC20))} -> 0.99805321 | ... AS20: {=IF(INDIRECT(AS$13&$AC20)=0,NA(),INDIRECT(AS$13&$AC20))} -> #N/A | AV20: 11 | AW20: Novembre
D21: 000 | E21: 2013 | F21: del15_cc | S21: 0.70591279 | W21: 7 | X21: 01f | Y21: =Z20+1 -> 339 | Z21: =Y21+(Z20-Y20) -> 392 | AC21: =AC20+1 -> 75 | AD21: {=IF(INDIRECT(AD$13&$AC21)=0,NA(),INDIRECT(AD$13&$AC21))} -> 01a | AE21: {=IF(INDIRECT(AE$13&$AC21)=0,NA(),INDIRECT(AE$13&$AC21))} -> 2013 | AF21: {=IF(INDIRECT(AF$13&$AC21)=0,NA(),INDIRECT(AF$13&$AC21))} -> del15_cc | AG21: {=IF(INDIRECT(AG$13&$AC21)=0,NA(),INDIRECT(AG$13&$AC21))} -> #N/A | AH21: {=IF(INDIRECT(AH$13&$AC21)=0,NA(),INDIRECT(AH$13&$AC21))} -> #N/A | AI21: {=IF(INDIRECT(AI$13&$AC21)=0,NA(),INDIRECT(AI$13&$AC21))} -> #N/A | AJ21: {=IF(INDIRECT(AJ$13&$AC21)=0,NA(),INDIRECT(AJ$13&$AC21))} -> #N/A | AK21: {=IF(INDIRECT(AK$13&$AC21)=0,NA(),INDIRECT(AK$13&$AC21))} -> #N/A | ... AS21: {=IF(INDIRECT(AS$13&$AC21)=0,NA(),INDIRECT(AS$13&$AC21))} -> 0.76167934 | AV21: 12 | AW21: Décembre
D22: 000 | E22: 2014 | F22: del15_cc | S22: 0.87761211 | W22: 8 | X22: 01g | Y22: =Z21+1 -> 393 | Z22: =Y22+(Z21-Y21) -> 446 | AC22: =AC21+1 -> 76 | AD22: {=IF(INDIRECT(AD$13&$AC22)=0,NA(),INDIRECT(AD$13&$AC22))} -> 01a | AE22: {=IF(INDIRECT(AE$13&$AC22)=0,NA(),INDIRECT(AE$13&$AC22))} -> 2014 | AF22: {=IF(INDIRECT(AF$13&$AC22)=0,NA(),INDIRECT(AF$13&$AC22))} -> del15_cc | AG22: {=IF(INDIRECT(AG$13&$AC22)=0,NA(),INDIRECT(AG$13&$AC22))} -> #N/A | AH22: {=IF(INDIRECT(AH$13&$AC22)=0,NA(),INDIRECT(AH$13&$AC22))} -> #N/A | AI22: {=IF(INDIRECT(AI$13&$AC22)=0,NA(),INDIRECT(AI$13&$AC22))} -> #N/A | AJ22: {=IF(INDIRECT(AJ$13&$AC22)=0,NA(),INDIRECT(AJ$13&$AC22))} -> #N/A | AK22: {=IF(INDIRECT(AK$13&$AC22)=0,NA(),INDIRECT(AK$13&$AC22))} -> #N/A | ... AS22: {=IF(INDIRECT(AS$13&$AC22)=0,NA(),INDIRECT(AS$13&$AC22))} -> 0.9246031
D23: 000 | E23: 2015 | F23: del15_cc | S23: 0.88970316 | W23: 9 | X23: 01h | Y23: =Z22+1 -> 447 | Z23: =Y23+(Z22-Y22) -> 500 | AC23: =AC22+1 -> 77 | AD23: {=IF(INDIRECT(AD$13&$AC23)=0,NA(),INDIRECT(AD$13&$AC23))} -> 01a | AE23: {=IF(INDIRECT(AE$13&$AC23)=0,NA(),INDIRECT(AE$13&$AC23))} -> 2015 | AF23: {=IF(INDIRECT(AF$13&$AC23)=0,NA(),INDIRECT(AF$13&$AC23))} -> del15_cc | AG23: {=IF(INDIRECT(AG$13&$AC23)=0,NA(),INDIRECT(AG$13&$AC23))} -> #N/A | AH23: {=IF(INDIRECT(AH$13&$AC23)=0,NA(),INDIRECT(AH$13&$AC23))} -> #N/A | AI23: {=IF(INDIRECT(AI$13&$AC23)=0,NA(),INDIRECT(AI$13&$AC23))} -> #N/A | AJ23: {=IF(INDIRECT(AJ$13&$AC23)=0,NA(),INDIRECT(AJ$13&$AC23))} -> #N/A | AK23: {=IF(INDIRECT(AK$13&$AC23)=0,NA(),INDIRECT(AK$13&$AC23))} -> #N/A | ... AS23: {=IF(INDIRECT(AS$13&$AC23)=0,NA(),INDIRECT(AS$13&$AC23))} -> 0.95843991
D24: 000 | E24: 2013 | F24: del15_mm | G24: 0.67084786 | H24: 0.68142372 | I24: 0.63974581 | J24: 0.6565671 | K24: 0.62938869 | L24: 0.795763 | M24: 0.86475952 | N24: 0.84611036 | O24: 0.84786838 | P24: 0.84146989 | Q24: 0.77592954 | R24: 0.8309244 | W24: 10 | X24: 01i | Y24: =Z23+1 -> 501 | Z24: =Y24+(Z23-Y23) -> 554 | AC24: =AC23+1 -> 78 | AD24: {=IF(INDIRECT(AD$13&$AC24)=0,NA(),INDIRECT(AD$13&$AC24))} -> 01a | AE24: {=IF(INDIRECT(AE$13&$AC24)=0,NA(),INDIRECT(AE$13&$AC24))} -> 2013 | AF24: {=IF(INDIRECT(AF$13&$AC24)=0,NA(),INDIRECT(AF$13&$AC24))} -> del15_mm | AG24: {=IF(INDIRECT(AG$13&$AC24)=0,NA(),INDIRECT(AG$13&$AC24))} -> 0.7577942 | AH24: {=IF(INDIRECT(AH$13&$AC24)=0,NA(),INDIRECT(AH$13&$AC24))} -> 0.73294757 | AI24: {=IF(INDIRECT(AI$13&$AC24)=0,NA(),INDIRECT(AI$13&$AC24))} -> 0.64295464 | AJ24: {=IF(INDIRECT(AJ$13&$AC24)=0,NA(),INDIRECT(AJ$13&$AC24))} -> 0.62567982 | AK24: {=IF(INDIRECT(AK$13&$AC24)=0,NA(),INDIRECT(AK$13&$AC24))} -> 0.71577009 | ... AS24: {=IF(INDIRECT(AS$13&$AC24)=0,NA(),INDIRECT(AS$13&$AC24))} -> #N/A
D25: 000 | E25: 2014 | F25: del15_mm | G25: 0.88318407 | H25: 0.89068083 | I25: 0.84317486 | J25: 0.85981529 | K25: 0.83864919 | L25: 0.89595799 | M25: 0.92545029 | N25: 0.91442736 | O25: 0.90610496 | P25: 0.93707503 | Q25: 0.90474765 | R25: 0.93255978 | W25: 11 | X25: 01j | Y25: =Z24+1 -> 555 | Z25: =Y25+(Z24-Y24) -> 608 | AC25: =AC24+1 -> 79 | AD25: {=IF(INDIRECT(AD$13&$AC25)=0,NA(),INDIRECT(AD$13&$AC25))} -> 01a | AE25: {=IF(INDIRECT(AE$13&$AC25)=0,NA(),INDIRECT(AE$13&$AC25))} -> 2014 | AF25: {=IF(INDIRECT(AF$13&$AC25)=0,NA(),INDIRECT(AF$13&$AC25))} -> del15_mm | AG25: {=IF(INDIRECT(AG$13&$AC25)=0,NA(),INDIRECT(AG$13&$AC25))} -> 0.9550554 | AH25: {=IF(INDIRECT(AH$13&$AC25)=0,NA(),INDIRECT(AH$13&$AC25))} -> 0.84958368 | AI25: {=IF(INDIRECT(AI$13&$AC25)=0,NA(),INDIRECT(AI$13&$AC25))} -> 0.72034254 | AJ25: {=IF(INDIRECT(AJ$13&$AC25)=0,NA(),INDIRECT(AJ$13&$AC25))} -> 0.98442507 | AK25: {=IF(INDIRECT(AK$13&$AC25)=0,NA(),INDIRECT(AK$13&$AC25))} -> 0.9948441 | ... AS25: {=IF(INDIRECT(AS$13&$AC25)=0,NA(),INDIRECT(AS$13&$AC25))} -> #N/A
D26: 000 | E26: 2015 | F26: del15_mm | G26: 0.9023978 | H26: 0.89945448 | I26: 0.86764088 | J26: 0.87989605 | K26: 0.84540451 | L26: 0.89343015 | M26: 0.93215764 | W26: 12 | X26: 01k | Y26: =Z25+1 -> 609 | Z26: =Y26+(Z25-Y25) -> 662 | AC26: =AC25+1 -> 80 | AD26: {=IF(INDIRECT(AD$13&$AC26)=0,NA(),INDIRECT(AD$13&$AC26))} -> 01a | AE26: {=IF(INDIRECT(AE$13&$AC26)=0,NA(),INDIRECT(AE$13&$AC26))} -> 2015 | AF26: {=IF(INDIRECT(AF$13&$AC26)=0,NA(),INDIRECT(AF$13&$AC26))} -> del15_mm | AG26: {=IF(INDIRECT(AG$13&$AC26)=0,NA(),INDIRECT(AG$13&$AC26))} -> 0.98361271 | AH26: {=IF(INDIRECT(AH$13&$AC26)=0,NA(),INDIRECT(AH$13&$AC26))} -> 0.89302753 | AI26: {=IF(INDIRECT(AI$13&$AC26)=0,NA(),INDIRECT(AI$13&$AC26))} -> 0.89977713 | AJ26: {=IF(INDIRECT(AJ$13&$AC26)=0,NA(),INDIRECT(AJ$13&$AC26))} -> 0.98977213 | AK26: {=IF(INDIRECT(AK$13&$AC26)=0,NA(),INDIRECT(AK$13&$AC26))} -> 0.96974427 | ... AS26: {=IF(INDIRECT(AS$13&$AC26)=0,NA(),INDIRECT(AS$13&$AC26))} -> #N/A
D27: 000 | E27: 2013 | F27: minima_cc | S27: 0.92382297 | W27: 13 | X27: 01l | Y27: =Z26+1 -> 663 | Z27: =Y27+(Z26-Y26) -> 716 | AC27: =AC26+1 -> 81 | AD27: {=IF(INDIRECT(AD$13&$AC27)=0,NA(),INDIRECT(AD$13&$AC27))} -> 01a | AE27: {=IF(INDIRECT(AE$13&$AC27)=0,NA(),INDIRECT(AE$13&$AC27))} -> 2013 | AF27: {=IF(INDIRECT(AF$13&$AC27)=0,NA(),INDIRECT(AF$13&$AC27))} -> minima_cc | AG27: {=IF(INDIRECT(AG$13&$AC27)=0,NA(),INDIRECT(AG$13&$AC27))} -> #N/A | AH27: {=IF(INDIRECT(AH$13&$AC27)=0,NA(),INDIRECT(AH$13&$AC27))} -> #N/A | AI27: {=IF(INDIRECT(AI$13&$AC27)=0,NA(),INDIRECT(AI$13&$AC27))} -> #N/A | AJ27: {=IF(INDIRECT(AJ$13&$AC27)=0,NA(),INDIRECT(AJ$13&$AC27))} -> #N/A | AK27: {=IF(INDIRECT(AK$13&$AC27)=0,NA(),INDIRECT(AK$13&$AC27))} -> #N/A | ... AS27: {=IF(INDIRECT(AS$13&$AC27)=0,NA(),INDIRECT(AS$13&$AC27))} -> 0.85010516
D28: 000 | E28: 2014 | F28: minima_cc | S28: 0.96591766 | W28: 14 | X28: 01m | Y28: =Z27+1 -> 717 | Z28: =Y28+(Z27-Y27) -> 770 | AC28: =AC27+1 -> 82 | AD28: {=IF(INDIRECT(AD$13&$AC28)=0,NA(),INDIRECT(AD$13&$AC28))} -> 01a | AE28: {=IF(INDIRECT(AE$13&$AC28)=0,NA(),INDIRECT(AE$13&$AC28))} -> 2014 | AF28: {=IF(INDIRECT(AF$13&$AC28)=0,NA(),INDIRECT(AF$13&$AC28))} -> minima_cc | AG28: {=IF(INDIRECT(AG$13&$AC28)=0,NA(),INDIRECT(AG$13&$AC28))} -> #N/A | AH28: {=IF(INDIRECT(AH$13&$AC28)=0,NA(),INDIRECT(AH$13&$AC28))} -> #N/A | AI28: {=IF(INDIRECT(AI$13&$AC28)=0,NA(),INDIRECT(AI$13&$AC28))} -> #N/A | AJ28: {=IF(INDIRECT(AJ$13&$AC28)=0,NA(),INDIRECT(AJ$13&$AC28))} -> #N/A | AK28: {=IF(INDIRECT(AK$13&$AC28)=0,NA(),INDIRECT(AK$13&$AC28))} -> #N/A | ... AS28: {=IF(INDIRECT(AS$13&$AC28)=0,NA(),INDIRECT(AS$13&$AC28))} -> 0.9899145
D29: 000 | E29: 2015 | F29: minima_cc | S29: 0.95042381 | W29: 15 | X29: 01n | Y29: =Z28+1 -> 771 | Z29: =Y29+(Z28-Y28) -> 824 | AC29: =AC28+1 -> 83 | AD29: {=IF(INDIRECT(AD$13&$AC29)=0,NA(),INDIRECT(AD$13&$AC29))} -> 01a | AE29: {=IF(INDIRECT(AE$13&$AC29)=0,NA(),INDIRECT(AE$13&$AC29))} -> 2015 | AF29: {=IF(INDIRECT(AF$13&$AC29)=0,NA(),INDIRECT(AF$13&$AC29))} -> minima_cc | AG29: {=IF(INDIRECT(AG$13&$AC29)=0,NA(),INDIRECT(AG$13&$AC29))} -> #N/A | AH29: {=IF(INDIRECT(AH$13&$AC29)=0,NA(),INDIRECT(AH$13&$AC29))} -> #N/A | AI29: {=IF(INDIRECT(AI$13&$AC29)=0,NA(),INDIRECT(AI$13&$AC29))} -> #N/A | AJ29: {=IF(INDIRECT(AJ$13&$AC29)=0,NA(),INDIRECT(AJ$13&$AC29))} -> #N/A | AK29: {=IF(INDIRECT(AK$13&$AC29)=0,NA(),INDIRECT(AK$13&$AC29))} -> #N/A | ... AS29: {=IF(INDIRECT(AS$13&$AC29)=0,NA(),INDIRECT(AS$13&$AC29))} -> 0.98810694
D30: 000 | E30: 2013 | F30: minima_mm | G30: 0.88438483 | H30: 0.91807654 | I30: 0.92600858 | J30: 0.92167165 | K30: 0.90007517 | L30: 0.95158496 | M30: 0.96509678 | N30: 0.94678851 | O30: 0.9364014 | P30: 0.94697695 | Q30: 0.93796867 | R30: 0.94702835 | W30: 16 | X30: 01o | Y30: =Z29+1 -> 825 | Z30: =Y30+(Z29-Y29) -> 878 | AC30: =AC29+1 -> 84 | AD30: {=IF(INDIRECT(AD$13&$AC30)=0,NA(),INDIRECT(AD$13&$AC30))} -> 01a | AE30: {=IF(INDIRECT(AE$13&$AC30)=0,NA(),INDIRECT(AE$13&$AC30))} -> 2013 | AF30: {=IF(INDIRECT(AF$13&$AC30)=0,NA(),INDIRECT(AF$13&$AC30))} -> minima_mm | AG30: {=IF(INDIRECT(AG$13&$AC30)=0,NA(),INDIRECT(AG$13&$AC30))} -> 0.8870709 | AH30: {=IF(INDIRECT(AH$13&$AC30)=0,NA(),INDIRECT(AH$13&$AC30))} -> 0.86396435 | AI30: {=IF(INDIRECT(AI$13&$AC30)=0,NA(),INDIRECT(AI$13&$AC30))} -> 0.69507411 | AJ30: {=IF(INDIRECT(AJ$13&$AC30)=0,NA(),INDIRECT(AJ$13&$AC30))} -> 0.68631351 | AK30: {=IF(INDIRECT(AK$13&$AC30)=0,NA(),INDIRECT(AK$13&$AC30))} -> 0.81636401 | ... AS30: {=IF(INDIRECT(AS$13&$AC30)=0,NA(),INDIRECT(AS$13&$AC30))} -> #N/A
D31: 000 | E31: 2014 | F31: minima_mm | G31: 0.97061866 | H31: 0.97126658 | I31: 0.95729042 | J31: 0.96356318 | K31: 0.96324365 | L31: 0.96723488 | M31: 0.96767888 | N31: 0.9679087 | O31: 0.96561424 | P31: 0.97225354 | Q31: 0.95947513 | R31: 0.96857976 | W31: 17 | X31: 01p | Y31: =Z30+1 -> 879 | Z31: =Y31+(Z30-Y30) -> 932 | AC31: =AC30+1 -> 85 | AD31: {=IF(INDIRECT(AD$13&$AC31)=0,NA(),INDIRECT(AD$13&$AC31))} -> 01a | AE31: {=IF(INDIRECT(AE$13&$AC31)=0,NA(),INDIRECT(AE$13&$AC31))} -> 2014 | AF31: {=IF(INDIRECT(AF$13&$AC31)=0,NA(),INDIRECT(AF$13&$AC31))} -> minima_mm | AG31: {=IF(INDIRECT(AG$13&$AC31)=0,NA(),INDIRECT(AG$13&$AC31))} -> 0.98896085 | AH31: {=IF(INDIRECT(AH$13&$AC31)=0,NA(),INDIRECT(AH$13&$AC31))} -> 0.98746867 | AI31: {=IF(INDIRECT(AI$13&$AC31)=0,NA(),INDIRECT(AI$13&$AC31))} -> 0.98691816 | AJ31: {=IF(INDIRECT(AJ$13&$AC31)=0,NA(),INDIRECT(AJ$13&$AC31))} -> 0.98537254 | AK31: {=IF(INDIRECT(AK$13&$AC31)=0,NA(),INDIRECT(AK$13&$AC31))} -> 0.98862461 | ... AS31: {=IF(INDIRECT(AS$13&$AC31)=0,NA(),INDIRECT(AS$13&$AC31))} -> #N/A
D32: 000 | E32: 2015 | F32: minima_mm | G32: 0.94457077 | H32: 0.95166803 | I32: 0.94452263 | J32: 0.94982881 | K32: 0.94181852 | L32: 0.95904851 | M32: 0.96065737 | W32: 18 | X32: 01q | Y32: =Z31+1 -> 933 | Z32: =Y32+(Z31-Y31) -> 986 | AC32: =AC31+1 -> 86 | AD32: {=IF(INDIRECT(AD$13&$AC32)=0,NA(),INDIRECT(AD$13&$AC32))} -> 01a | AE32: {=IF(INDIRECT(AE$13&$AC32)=0,NA(),INDIRECT(AE$13&$AC32))} -> 2015 | AF32: {=IF(INDIRECT(AF$13&$AC32)=0,NA(),INDIRECT(AF$13&$AC32))} -> minima_mm | AG32: {=IF(INDIRECT(AG$13&$AC32)=0,NA(),INDIRECT(AG$13&$AC32))} -> 0.98439376 | AH32: {=IF(INDIRECT(AH$13&$AC32)=0,NA(),INDIRECT(AH$13&$AC32))} -> 0.98565821 | AI32: {=IF(INDIRECT(AI$13&$AC32)=0,NA(),INDIRECT(AI$13&$AC32))} -> 0.98893669 | AJ32: {=IF(INDIRECT(AJ$13&$AC32)=0,NA(),INDIRECT(AJ$13&$AC32))} -> 0.9888668 | AK32: {=IF(INDIRECT(AK$13&$AC32)=0,NA(),INDIRECT(AK$13&$AC32))} -> 0.99105602 | ... AS32: {=IF(INDIRECT(AS$13&$AC32)=0,NA(),INDIRECT(AS$13&$AC32))} -> #N/A
D33: 000 | E33: 2013 | F33: nbappabo_cc | S33: 21022545 | W33: 19 | X33: 01r | Y33: =Z32+1 -> 987 | Z33: =Y33+(Z32-Y32) -> 1040 | AC33: =AC32+1 -> 87 | AD33: {=IF(INDIRECT(AD$13&$AC33)=0,NA(),INDIRECT(AD$13&$AC33))} -> 01a | AE33: {=IF(INDIRECT(AE$13&$AC33)=0,NA(),INDIRECT(AE$13&$AC33))} -> 2013 | AF33: {=IF(INDIRECT(AF$13&$AC33)=0,NA(),INDIRECT(AF$13&$AC33))} -> nbappabo_cc | AG33: {=IF(INDIRECT(AG$13&$AC33)=0,NA(),INDIRECT(AG$13&$AC33))} -> #N/A | AH33: {=IF(INDIRECT(AH$13&$AC33)=0,NA(),INDIRECT(AH$13&$AC33))} -> #N/A | AI33: {=IF(INDIRECT(AI$13&$AC33)=0,NA(),INDIRECT(AI$13&$AC33))} -> #N/A | AJ33: {=IF(INDIRECT(AJ$13&$AC33)=0,NA(),INDIRECT(AJ$13&$AC33))} -> #N/A | AK33: {=IF(INDIRECT(AK$13&$AC33)=0,NA(),INDIRECT(AK$13&$AC33))} -> #N/A | ... AS33: {=IF(INDIRECT(AS$13&$AC33)=0,NA(),INDIRECT(AS$13&$AC33))} -> 138538
D34: 000 | E34: 2014 | F34: nbappabo_cc | S34: 18914874 | W34: 20 | X34: 01s | Y34: =Z33+1 -> 1041 | Z34: =Y34+(Z33-Y33) -> 1094 | AC34: =AC33+1 -> 88 | AD34: {=IF(INDIRECT(AD$13&$AC34)=0,NA(),INDIRECT(AD$13&$AC34))} -> 01a | AE34: {=IF(INDIRECT(AE$13&$AC34)=0,NA(),INDIRECT(AE$13&$AC34))} -> 2014 | AF34: {=IF(INDIRECT(AF$13&$AC34)=0,NA(),INDIRECT(AF$13&$AC34))} -> nbappabo_cc | AG34: {=IF(INDIRECT(AG$13&$AC34)=0,NA(),INDIRECT(AG$13&$AC34))} -> #N/A | AH34: {=IF(INDIRECT(AH$13&$AC34)=0,NA(),INDIRECT(AH$13&$AC34))} -> #N/A | AI34: {=IF(INDIRECT(AI$13&$AC34)=0,NA(),INDIRECT(AI$13&$AC34))} -> #N/A | AJ34: {=IF(INDIRECT(AJ$13&$AC34)=0,NA(),INDIRECT(AJ$13&$AC34))} -> #N/A | AK34: {=IF(INDIRECT(AK$13&$AC34)=0,NA(),INDIRECT(AK$13&$AC34))} -> #N/A | ... AS34: {=IF(INDIRECT(AS$13&$AC34)=0,NA(),INDIRECT(AS$13&$AC34))} -> 138479
D35: 000 | E35: 2015 | F35: nbappabo_cc | S35: 18116096 | W35: 21 | X35: 01t | Y35: =Z34+1 -> 1095 | Z35: =Y35+(Z34-Y34) -> 1148 | AC35: =AC34+1 -> 89 | AD35: {=IF(INDIRECT(AD$13&$AC35)=0,NA(),INDIRECT(AD$13&$AC35))} -> 01a | AE35: {=IF(INDIRECT(AE$13&$AC35)=0,NA(),INDIRECT(AE$13&$AC35))} -> 2015 | AF35: {=IF(INDIRECT(AF$13&$AC35)=0,NA(),INDIRECT(AF$13&$AC35))} -> nbappabo_cc | AG35: {=IF(INDIRECT(AG$13&$AC35)=0,NA(),INDIRECT(AG$13&$AC35))} -> #N/A | AH35: {=IF(INDIRECT(AH$13&$AC35)=0,NA(),INDIRECT(AH$13&$AC35))} -> #N/A | AI35: {=IF(INDIRECT(AI$13&$AC35)=0,NA(),INDIRECT(AI$13&$AC35))} -> #N/A | AJ35: {=IF(INDIRECT(AJ$13&$AC35)=0,NA(),INDIRECT(AJ$13&$AC35))} -> #N/A | AK35: {=IF(INDIRECT(AK$13&$AC35)=0,NA(),INDIRECT(AK$13&$AC35))} -> #N/A | ... AS35: {=IF(INDIRECT(AS$13&$AC35)=0,NA(),INDIRECT(AS$13&$AC35))} -> 145611
D36: 000 | E36: 2013 | F36: nbappabo_mm | G36: 3722169 | H36: 3795007 | I36: 3062849 | J36: 2738084 | K36: 2719818 | L36: 2403371 | M36: 2581247 | N36: 2533940 | O36: 2897324 | P36: 2865073 | Q36: 2681277 | R36: 2636897 | W36: 22 | X36: 01u | Y36: =Z35+1 -> 1149 | Z36: =Y36+(Z35-Y35) -> 1202 | AC36: =AC35+1 -> 90 | AD36: {=IF(INDIRECT(AD$13&$AC36)=0,NA(),INDIRECT(AD$13&$AC36))} -> 01a | AE36: {=IF(INDIRECT(AE$13&$AC36)=0,NA(),INDIRECT(AE$13&$AC36))} -> 2013 | AF36: {=IF(INDIRECT(AF$13&$AC36)=0,NA(),INDIRECT(AF$13&$AC36))} -> nbappabo_mm | AG36: {=IF(INDIRECT(AG$13&$AC36)=0,NA(),INDIRECT(AG$13&$AC36))} -> 23642 | AH36: {=IF(INDIRECT(AH$13&$AC36)=0,NA(),INDIRECT(AH$13&$AC36))} -> 24600 | AI36: {=IF(INDIRECT(AI$13&$AC36)=0,NA(),INDIRECT(AI$13&$AC36))} -> 21698 | AJ36: {=IF(INDIRECT(AJ$13&$AC36)=0,NA(),INDIRECT(AJ$13&$AC36))} -> 18665 | AK36: {=IF(INDIRECT(AK$13&$AC36)=0,NA(),INDIRECT(AK$13&$AC36))} -> 17657 | ... AS36: {=IF(INDIRECT(AS$13&$AC36)=0,NA(),INDIRECT(AS$13&$AC36))} -> #N/A
D37: 000 | E37: 2014 | F37: nbappabo_mm | G37: 3081777 | H37: 3099575 | I37: 2693926 | J37: 2437927 | K37: 2453625 | L37: 2457682 | M37: 2690362 | N37: 2549451 | O37: 3369402 | P37: 2919375 | Q37: 2546330 | R37: 2668942 | W37: 23 | X37: 01v | Y37: =Z36+1 -> 1203 | Z37: =Y37+(Z36-Y36) -> 1256 | AC37: =AC36+1 -> 91 | AD37: {=IF(INDIRECT(AD$13&$AC37)=0,NA(),INDIRECT(AD$13&$AC37))} -> 01a | AE37: {=IF(INDIRECT(AE$13&$AC37)=0,NA(),INDIRECT(AE$13&$AC37))} -> 2014 | AF37: {=IF(INDIRECT(AF$13&$AC37)=0,NA(),INDIRECT(AF$13&$AC37))} -> nbappabo_mm | AG37: {=IF(INDIRECT(AG$13&$AC37)=0,NA(),INDIRECT(AG$13&$AC37))} -> 23158 | AH37: {=IF(INDIRECT(AH$13&$AC37)=0,NA(),INDIRECT(AH$13&$AC37))} -> 23987 | AI37: {=IF(INDIRECT(AI$13&$AC37)=0,NA(),INDIRECT(AI$13&$AC37))} -> 20624 | AJ37: {=IF(INDIRECT(AJ$13&$AC37)=0,NA(),INDIRECT(AJ$13&$AC37))} -> 17438 | AK37: {=IF(INDIRECT(AK$13&$AC37)=0,NA(),INDIRECT(AK$13&$AC37))} -> 16602 | ... AS37: {=IF(INDIRECT(AS$13&$AC37)=0,NA(),INDIRECT(AS$13&$AC37))} -> #N/A
D38: 000 | E38: 2015 | F38: nbappabo_mm | G38: 2787136 | H38: 2770296 | I38: 2740400 | J38: 2453567 | K38: 2171119 | L38: 2541703 | M38: 2651875 | W38: 24 | X38: 01w | Y38: =Z37+1 -> 1257 | Z38: =Y38+(Z37-Y37) -> 1310 | AC38: =AC37+1 -> 92 | AD38: {=IF(INDIRECT(AD$13&$AC38)=0,NA(),INDIRECT(AD$13&$AC38))} -> 01a | AE38: {=IF(INDIRECT(AE$13&$AC38)=0,NA(),INDIRECT(AE$13&$AC38))} -> 2015 | AF38: {=IF(INDIRECT(AF$13&$AC38)=0,NA(),INDIRECT(AF$13&$AC38))} -> nbappabo_mm | AG38: {=IF(INDIRECT(AG$13&$AC38)=0,NA(),INDIRECT(AG$13&$AC38))} -> 21746 | AH38: {=IF(INDIRECT(AH$13&$AC38)=0,NA(),INDIRECT(AH$13&$AC38))} -> 22184 | AI38: {=IF(INDIRECT(AI$13&$AC38)=0,NA(),INDIRECT(AI$13&$AC38))} -> 24893 | AJ38: {=IF(INDIRECT(AJ$13&$AC38)=0,NA(),INDIRECT(AJ$13&$AC38))} -> 20708 | AK38: {=IF(INDIRECT(AK$13&$AC38)=0,NA(),INDIRECT(AK$13&$AC38))} -> 17612 | ... AS38: {=IF(INDIRECT(AS$13&$AC38)=0,NA(),INDIRECT(AS$13&$AC38))} -> #N/A
D39: 000 | E39: 2013 | F39: nbcourriers_cc | S39: 45302301 | W39: 25 | X39: 01x | Y39: =Z38+1 -> 1311 | Z39: =Y39+(Z38-Y38) -> 1364 | AC39: =AC38+1 -> 93 | AD39: {=IF(INDIRECT(AD$13&$AC39)=0,NA(),INDIRECT(AD$13&$AC39))} -> 01a | AE39: {=IF(INDIRECT(AE$13&$AC39)=0,NA(),INDIRECT(AE$13&$AC39))} -> 2013 | AF39: {=IF(INDIRECT(AF$13&$AC39)=0,NA(),INDIRECT(AF$13&$AC39))} -> nbcourriers_cc | AG39: {=IF(INDIRECT(AG$13&$AC39)=0,NA(),INDIRECT(AG$13&$AC39))} -> #N/A | AH39: {=IF(INDIRECT(AH$13&$AC39)=0,NA(),INDIRECT(AH$13&$AC39))} -> #N/A | AI39: {=IF(INDIRECT(AI$13&$AC39)=0,NA(),INDIRECT(AI$13&$AC39))} -> #N/A | AJ39: {=IF(INDIRECT(AJ$13&$AC39)=0,NA(),INDIRECT(AJ$13&$AC39))} -> #N/A | AK39: {=IF(INDIRECT(AK$13&$AC39)=0,NA(),INDIRECT(AK$13&$AC39))} -> #N/A | ... AS39: {=IF(INDIRECT(AS$13&$AC39)=0,NA(),INDIRECT(AS$13&$AC39))} -> 341756
D40: 000 | E40: 2014 | F40: nbcourriers_cc | S40: 47174751 | W40: 26 | X40: 01y | Y40: =Z39+1 -> 1365 | Z40: =Y40+(Z39-Y39) -> 1418 | AC40: =AC39+1 -> 94 | AD40: {=IF(INDIRECT(AD$13&$AC40)=0,NA(),INDIRECT(AD$13&$AC40))} -> 01a | AE40: {=IF(INDIRECT(AE$13&$AC40)=0,NA(),INDIRECT(AE$13&$AC40))} -> 2014 | AF40: {=IF(INDIRECT(AF$13&$AC40)=0,NA(),INDIRECT(AF$13&$AC40))} -> nbcourriers_cc | AG40: {=IF(INDIRECT(AG$13&$AC40)=0,NA(),INDIRECT(AG$13&$AC40))} -> #N/A | AH40: {=IF(INDIRECT(AH$13&$AC40)=0,NA(),INDIRECT(AH$13&$AC40))} -> #N/A | AI40: {=IF(INDIRECT(AI$13&$AC40)=0,NA(),INDIRECT(AI$13&$AC40))} -> #N/A | AJ40: {=IF(INDIRECT(AJ$13&$AC40)=0,NA(),INDIRECT(AJ$13&$AC40))} -> #N/A | AK40: {=IF(INDIRECT(AK$13&$AC40)=0,NA(),INDIRECT(AK$13&$AC40))} -> #N/A | ... AS40: {=IF(INDIRECT(AS$13&$AC40)=0,NA(),INDIRECT(AS$13&$AC40))} -> 325674
D41: 000 | E41: 2015 | F41: nbcourriers_cc | S41: 52185995 | W41: 27 | X41: 01z | Y41: =Z40+1 -> 1419 | Z41: =Y41+(Z40-Y40) -> 1472 | AC41: =AC40+1 -> 95 | AD41: {=IF(INDIRECT(AD$13&$AC41)=0,NA(),INDIRECT(AD$13&$AC41))} -> 01a | AE41: {=IF(INDIRECT(AE$13&$AC41)=0,NA(),INDIRECT(AE$13&$AC41))} -> 2015 | AF41: {=IF(INDIRECT(AF$13&$AC41)=0,NA(),INDIRECT(AF$13&$AC41))} -> nbcourriers_cc | AG41: {=IF(INDIRECT(AG$13&$AC41)=0,NA(),INDIRECT(AG$13&$AC41))} -> #N/A | AH41: {=IF(INDIRECT(AH$13&$AC41)=0,NA(),INDIRECT(AH$13&$AC41))} -> #N/A | AI41: {=IF(INDIRECT(AI$13&$AC41)=0,NA(),INDIRECT(AI$13&$AC41))} -> #N/A | AJ41: {=IF(INDIRECT(AJ$13&$AC41)=0,NA(),INDIRECT(AJ$13&$AC41))} -> #N/A | AK41: {=IF(INDIRECT(AK$13&$AC41)=0,NA(),INDIRECT(AK$13&$AC41))} -> #N/A | ... AS41: {=IF(INDIRECT(AS$13&$AC41)=0,NA(),INDIRECT(AS$13&$AC41))} -> 359288
D42: 000 | E42: 2013 | F42: nbcourriers_mm | G42: 7870380 | H42: 6504075 | I42: 6324662 | J42: 6059960 | K42: 5616371 | L42: 6129818 | M42: 6797035 | N42: 6166342 | O42: 7871469 | P42: 8611527 | Q42: 7876854 | R42: 8020474 | W42: 28 | X42: 02a | Y42: =Z41+1 -> 1473 | Z42: =Y42+(Z41-Y41) -> 1526 | AC42: =AC41+1 -> 96 | AD42: {=IF(INDIRECT(AD$13&$AC42)=0,NA(),INDIRECT(AD$13&$AC42))} -> 01a | AE42: {=IF(INDIRECT(AE$13&$AC42)=0,NA(),INDIRECT(AE$13&$AC42))} -> 2013 | AF42: {=IF(INDIRECT(AF$13&$AC42)=0,NA(),INDIRECT(AF$13&$AC42))} -> nbcourriers_mm | AG42: {=IF(INDIRECT(AG$13&$AC42)=0,NA(),INDIRECT(AG$13&$AC42))} -> 60546 | AH42: {=IF(INDIRECT(AH$13&$AC42)=0,NA(),INDIRECT(AH$13&$AC42))} -> 51467 | AI42: {=IF(INDIRECT(AI$13&$AC42)=0,NA(),INDIRECT(AI$13&$AC42))} -> 46712 | AJ42: {=IF(INDIRECT(AJ$13&$AC42)=0,NA(),INDIRECT(AJ$13&$AC42))} -> 43869 | AK42: {=IF(INDIRECT(AK$13&$AC42)=0,NA(),INDIRECT(AK$13&$AC42))} -> 44750 | ... AS42: {=IF(INDIRECT(AS$13&$AC42)=0,NA(),INDIRECT(AS$13&$AC42))} -> #N/A
D43: 000 | E43: 2014 | F43: nbcourriers_mm | G43: 8206649 | H43: 7021385 | I43: 6505347 | J43: 6363251 | K43: 5886743 | L43: 6268468 | M43: 6922908 | N43: 6563880 | O43: 8041653 | P43: 8448816 | Q43: 7939495 | R43: 8838654 | W43: 29 | X43: 02b | Y43: =Z42+1 -> 1527 | Z43: =Y43+(Z42-Y42) -> 1580 | AC43: =AC42+1 -> 97 | AD43: {=IF(INDIRECT(AD$13&$AC43)=0,NA(),INDIRECT(AD$13&$AC43))} -> 01a | AE43: {=IF(INDIRECT(AE$13&$AC43)=0,NA(),INDIRECT(AE$13&$AC43))} -> 2014 | AF43: {=IF(INDIRECT(AF$13&$AC43)=0,NA(),INDIRECT(AF$13&$AC43))} -> nbcourriers_mm | AG43: {=IF(INDIRECT(AG$13&$AC43)=0,NA(),INDIRECT(AG$13&$AC43))} -> 60699 | AH43: {=IF(INDIRECT(AH$13&$AC43)=0,NA(),INDIRECT(AH$13&$AC43))} -> 48620 | AI43: {=IF(INDIRECT(AI$13&$AC43)=0,NA(),INDIRECT(AI$13&$AC43))} -> 44324 | AJ43: {=IF(INDIRECT(AJ$13&$AC43)=0,NA(),INDIRECT(AJ$13&$AC43))} -> 43065 | AK43: {=IF(INDIRECT(AK$13&$AC43)=0,NA(),INDIRECT(AK$13&$AC43))} -> 39977 | ... AS43: {=IF(INDIRECT(AS$13&$AC43)=0,NA(),INDIRECT(AS$13&$AC43))} -> #N/A
D44: 000 | E44: 2015 | F44: nbcourriers_mm | G44: 8471869 | H44: 7194408 | I44: 7570987 | J44: 6968297 | K44: 6260123 | L44: 7720651 | M44: 7999660 | W44: 30 | X44: 02c | Y44: =Z43+1 -> 1581 | Z44: =Y44+(Z43-Y43) -> 1634 | AC44: =AC43+1 -> 98 | AD44: {=IF(INDIRECT(AD$13&$AC44)=0,NA(),INDIRECT(AD$13&$AC44))} -> 01a | AE44: {=IF(INDIRECT(AE$13&$AC44)=0,NA(),INDIRECT(AE$13&$AC44))} -> 2015 | AF44: {=IF(INDIRECT(AF$13&$AC44)=0,NA(),INDIRECT(AF$13&$AC44))} -> nbcourriers_mm | AG44: {=IF(INDIRECT(AG$13&$AC44)=0,NA(),INDIRECT(AG$13&$AC44))} -> 61115 | AH44: {=IF(INDIRECT(AH$13&$AC44)=0,NA(),INDIRECT(AH$13&$AC44))} -> 47115 | AI44: {=IF(INDIRECT(AI$13&$AC44)=0,NA(),INDIRECT(AI$13&$AC44))} -> 53606 | AJ44: {=IF(INDIRECT(AJ$13&$AC44)=0,NA(),INDIRECT(AJ$13&$AC44))} -> 47226 | AK44: {=IF(INDIRECT(AK$13&$AC44)=0,NA(),INDIRECT(AK$13&$AC44))} -> 43302 | ... AS44: {=IF(INDIRECT(AS$13&$AC44)=0,NA(),INDIRECT(AS$13&$AC44))} -> #N/A
...

Sheet tdb1_ems
C1: 2 | D1: ="Résultats de la CAF "&VLOOKUP(C1,'Base de donnée'!W15:X117,2) -> Résultats de la CAF 01a
D21: Tableau de bord stratégique mensuel
L49: =VLOOKUP(COUNT('Base de donnée'!AG32:AR32),'Base de donnée'!AV10:AW21,2,0)&" " &'Base de donnée'!AE17 -> Juillet 2015
R88: 1
K90: SOMMAIRE
F97: GERER LA RELATION CLIENT | R97: 3
F99: Gérer les contacts physiques | R99: 3
G100: Nombre de visites
G101: Les visites avec un temps d’attente ≤ 20 min
G102: Dispersion des caisses selon le temps d’attente à l’accueil inférieur à 20 minutes
F105: Gérer les contacts téléphoniques | R105: 4
G106: Evolution du nombre d’appels téléphoniques aboutis
G107: Le taux d’appels traités
G108: Dispersion des caisses selon la part des appels traités
G109: Le taux d’appels traités par un agent | R109: 5
G110: Dispersion des caisses selon le taux d'appels traités par un agent
F113: Gérer les courriers entrants | R113: 6
G114: Nombre de courriers arrivés
G115: Nombre de pièces arrivées
F120: TRAITER LES PRESTATIONS INDIVIDUELLES | R120: 7
F122: Traiter les prestations légales et déléguées | R122: 7
G123: Les pièces traitées en 15 jours ou moins
G124: Répartition des caisses selon le pourcentage de pièces traitées en 15 jours ou moins
F127: Gérer les prestations liées aux minima sociaux | R127: 8
G128: Les pièces traitées en moins de 10 jours (minima sociaux
G129: Répartition des caisses selon le pourcentage de pièces traitées en moins de 10 jours (minima sociaux)
F147: Indice PCAP : Littéralement, c'est la "période comparable de l'année N à l'année N-1. Il s'agit donc de la période allant du 1er janvier au dernier jour du mois clôturé,
F148: comparée à celle du 1er janvier au mois correspondant de l'année précédente.
F151: Indice ACM : C'est l' "année complète mobile". Il s'agit de la période allant des 12 derniers mois comparés aux 12 mois précédant ceux-ci.
F152: Exemple : ACM (octobre 2010). On compare la période allant de novembre 2009 à octobre 2010 à la période allant de novembre 2008 à octobre 2009.
R180: 2
J182: GERER LA RELATION CLIENT
F185: GERER LES CONTACTS PHYSIQUES
F188: Nombre de visites (en milliers)
G220: Janvier | H220: Février | I220: Mars | J220: Avril | K220: Mai | L220: Juin | M220: Juillet | N220: Août | O220: Septembre | P220: Octobre | Q220: Novembre | R220: Décembre
F221: ="Evo"&'Base de donnée'!AD122 & "/" & 'Base de donnée'!AD124 -> Evo/ | G221: =IFERROR(('Base de donnée'!AG56-'Base de donnée'!AG55)/'Base de donnée'!AG55,"") -> -0.71715989 | H221: =IFERROR(('Base de donnée'!AH56-'Base de donnée'!AH55)/'Base de donnée'!AH55,"") -> -0.77209417 | I221: =IFERROR(('Base de donnée'!AI56-'Base de donnée'!AI55)/'Base de donnée'!AI55,"") -> -0.7275079 | J221: =IFERROR(('Base de donnée'!AJ56-'Base de donnée'!AJ55)/'Base de donnée'!AJ55,"") -> -0.74542636 | K221: =IFERROR(('Base de donnée'!AK56-'Base de donnée'!AK55)/'Base de donnée'!AK55,"") -> -0.60568066 | L221: =IFERROR(('Base de donnée'!AL56-'Base de donnée'!AL55)/'Base de donnée'!AL55,"") -> -0.55273438 | M221: =IFERROR(('Base de donnée'!AM56-'Base de donnée'!AM55)/'Base de donnée'!AM55,"") -> -0.61538462 | N221: =IFERROR(('Base de donnée'!AN56-'Base de donnée'!AN55)/'Base de donnée'!AN55,"") | ... R221: =IFERROR(('Base de donnée'!AR56-'Base de donnée'!AR55)/'Base de donnée'!AR55,"")
F222: PCAP | G222: =IFERROR((SUM('Base de donnée'!$AG56:AG56)-SUM('Base de donnée'!$AG55:AG55))/SUM('Base de donnée'!$AG55:AG55),"") -> -0.71715989 | H222: =IFERROR((SUM('Base de donnée'!$AG56:AH56)-SUM('Base de donnée'!$AG55:AH55))/SUM('Base de donnée'!$AG55:AH55),"") -> -0.74261724 | I222: =IFERROR((SUM('Base de donnée'!$AG56:AI56)-SUM('Base de donnée'!$AG55:AI55))/SUM('Base de donnée'!$AG55:AI55),"") -> -0.73832005 | J222: =IFERROR((SUM('Base de donnée'!$AG56:AJ56)-SUM('Base de donnée'!$AG55:AJ55))/SUM('Base de donnée'!$AG55:AJ55),"") -> -0.73980268 | K222: =IFERROR((SUM('Base de donnée'!$AG56:AK56)-SUM('Base de donnée'!$AG55:AK55))/SUM('Base de donnée'!$AG55:AK55),"") -> -0.72475088 | L222: =IFERROR((SUM('Base de donnée'!$AG56:AL56)-SUM('Base de donnée'!$AG55:AL55))/SUM('Base de donnée'!$AG55:AL55),"") -> -0.70664714 | M222: =IFERROR((SUM('Base de donnée'!$AG56:AM56)-SUM('Base de donnée'!$AG55:AM55))/SUM('Base de donnée'!$AG55:AM55),"") -> -0.69948383 | N222: =IFERROR((SUM('Base de donnée'!$AG56:AN56)-SUM('Base de donnée'!$AG55:AN55))/SUM('Base de donnée'!$AG55:AN55),"") | ... R222: =IFERROR((SUM('Base de donnée'!$AG56:AR56)-SUM('Base de donnée'!$AG55:AR55))/SUM('Base de donnée'!$AG55:AR55),"")
F223: ACM | G223: =IFERROR((SUM('Base de donnée'!$AG56:AG56,'Base de donnée'!AH55:$AR55)-SUM('Base de donnée'!$AG55:AG55,'Base de donnée'!AH54:$AR54))/SUM('Base de donnée'!$AG55:AG55,'Base de donnée'!AH54:$AR54),"") -> -0.40427055 | H223: =IFERROR((SUM('Base de donnée'!$AG56:AH56,'Base de donnée'!AI55:$AR55)-SUM('Base de donnée'!$AG55:AH55,'Base de donnée'!AI54:$AR54))/SUM('Base de donnée'!$AG55:AH55,'Base de donnée'!AI54:$AR54),"") -> -0.48056479 | I223: =IFERROR((SUM('Base de donnée'!$AG56:AI56,'Base de donnée'!AJ55:$AR55)-SUM('Base de donnée'!$AG55:AI55,'Base de donnée'!AJ54:$AR54))/SUM('Base de donnée'!$AG55:AI55,'Base de donnée'!AJ54:$AR54),"") -> -0.53713394 | J223: =IFERROR((SUM('Base de donnée'!$AG56:AJ56,'Base de donnée'!AK55:$AR55)-SUM('Base de donnée'!$AG55:AJ55,'Base de donnée'!AK54:$AR54))/SUM('Base de donnée'!$AG55:AJ55,'Base de donnée'!AK54:$AR54),"") -> -0.59443924 | K223: =IFERROR((SUM('Base de donnée'!$AG56:AK56,'Base de donnée'!AL55:$AR55)-SUM('Base de donnée'!$AG55:AK55,'Base de donnée'!AL54:$AR54))/SUM('Base de donnée'!$AG55:AK55,'Base de donnée'!AL54:$AR54),"") -> -0.60682178 | L223: =IFERROR((SUM('Base de donnée'!$AG56:AL56,'Base de donnée'!AM55:$AR55)-SUM('Base de donnée'!$AG55:AL55,'Base de donnée'!AM54:$AR54))/SUM('Base de donnée'!$AG55:AL55,'Base de donnée'!AM54:$AR54),"") -> -0.62419704 | M223: =IFERROR((SUM('Base de donnée'!$AG56:AM56,'Base de donnée'!AN55:$AR55)-SUM('Base de donnée'!$AG55:AM55,'Base de donnée'!AN54:$AR54))/SUM('Base de donnée'!$AG55:AM55,'Base de donnée'!AN54:$AR54),"") -> -0.63565791 | N223: =IFERROR((SUM('Base de donnée'!$AG56:AN56,'Base de donnée'!AO55:$AR55)-SUM('Base de donnée'!$AG55:AN55,'Base de donnée'!AO54:$AR54))/SUM('Base de donnée'!$AG55:AN55,'Base de donnée'!AO54:$AR54),"") | ... Q223: =IFERROR((SUM('Base de donnée'!$AG56:AQ56,'Base de donnée'!AR55:$AR55)-SUM('Base de donnée'!$AG55:AQ55,'Base de donnée'!AR54:$AR54))/SUM('Base de donnée'!$AG55:AQ55,'Base de donnée'!AR54:$AR54),"") | R223: =IFERROR((SUM('Base de donnée'!$AG56:AR56,'Base de donnée'!$AR55:AS55)-SUM('Base de donnée'!$AG55:AR55,'Base de donnée'!$AR54:AS54))/SUM('Base de donnée'!$AG55:AR55,'Base de donnée'!$AR54:AS54),"")
F228: Les visites avec un temps d'attente inférieur à 20 minutes
G258: Janvier | H258: Février | I258: Mars | J258: Avril | K258: Mai | L258: Juin | M258: Juillet | N258: Août | O258: Septembre | P258: Octobre | Q258: Novembre | R258: Décembre
...

Sheet tdb1_ems_alerte
A1: numorg | B1: vide1 | C1: del15_cc | D1: minima_cc | E1: vis20_cc | F1: txapptragt_cc | G1: vide2 | H1: del15_mm0 | I1: minima_mm0 | J1: vis20_mm0 | K1: txapptragt_mm0 | L1: vide3 | M1: del | N1: min | O1: vis | P1: tel | Q1: ind
A2: 02c | C2: 0.73449245 | D2: 0.7177302 | E2: 0.64834758 | F2: 0.88218284 | H2: 0.82509926 | I2: 0.6755908 | J2: 0.45687953 | K2: 0.90546084 | M2: 3 | N2: 4 | O2: 4 | P2: 1 | Q2: 0.74568827
A3: 04c | C3: 0.79809555 | D3: 0.8529679 | E3: 0.71927025 | F3: 0.89171053 | H3: 0.86505359 | I3: 0.86267882 | J3: 0.90394089 | K3: 0.89889411 | M3: 1 | N3: 4 | O3: 2 | P3: 4 | Q3: 0.81551106
A4: 04t | C4: 0.71941934 | D4: 0.90436416 | E4: 0.78753236 | F4: 0.92625984 | H4: 0.87594945 | I4: 0.87842178 | J4: 0.95240511 | K4: 0.92370828 | M4: 1 | N4: 4 | O4: 1 | P4: 2 | Q4: 0.83439392
A5: 04w | C5: 0.84659499 | D5: 0.96757994 | E5: 0.63024739 | F5: 0.91908502 | H5: 0.98211485 | I5: 0.98085485 | J5: 0.73437706 | K5: 0.90066815 | M5: 1 | N5: 1 | O5: 3 | P5: 2 | Q5: 0.84087683
A6: 01m | C6: 0.66843456 | D6: 0.8886898 | E6: 0.95497513 | F6: 0.85369222 | H6: 0.70606953 | I6: 0.87860671 | J6: 0.96100253 | K6: 0.83931837 | M6: 3 | N6: 3 | O6: 2 | P6: 3 | Q6: 0.84144793
A7: 03a | C7: 0.78749914 | D7: 0.8522813 | E7: 0.8693881 | F7: 0.91403733 | H7: 0.82720068 | I7: 0.97685873 | J7: 0.94444833 | M7: 3 | N7: 1 | O7: 1 | P7: 4 | Q7: 0.85580147
A8: 01x | C8: 0.93457873 | D8: 0.99696729 | E8: 0.6336257 | F8: 0.88817209 | H8: 0.82937976 | I8: 0.99779943 | J8: 0.53996737 | K8: 0.79030501 | M8: 3 | N8: 1 | O8: 3 | P8: 4 | Q8: 0.86333595
A9: 04h | C9: 0.90686476 | D9: 0.92164785 | E9: 0.74266654 | F9: 0.8879083 | H9: 0.89903897 | I9: 0.92339893 | J9: 0.77682994 | K9: 0.87067801 | M9: 1 | N9: 2 | O9: 4 | P9: 4 | Q9: 0.86477186
A10: 04r | C10: 0.77688759 | D10: 0.87605782 | E10: 0.88722656 | F10: 0.9271056 | H10: 0.81199405 | I10: 0.89158187 | J10: 0.88317967 | K10: 0.90732696 | M10: 3 | N10: 4 | O10: 2 | P10: 2 | Q10: 0.86681939
A11: 01h | C11: 0.82096833 | D11: 0.89473579 | E11: 0.87062082 | F11: 0.89581633 | H11: 0.91620048 | I11: 0.9130033 | J11: 0.85326777 | K11: 0.82453544 | M11: 1 | N11: 2 | O11: 1 | P11: 4 | Q11: 0.87053532
A12: 02k | C12: 0.80552693 | D12: 0.89912307 | E12: 0.83853431 | F12: 0.94219504 | H12: 0.81639162 | I12: 0.92086111 | J12: 0.83936022 | K12: 0.89251075 | M12: 3 | N12: 2 | O12: 4 | P12: 4 | Q12: 0.87134483
A13: 04p | C13: 0.73650558 | D13: 0.88853323 | E13: 0.96851311 | F13: 0.91336098 | H13: 0.73470496 | I13: 0.88103615 | J13: 0.96892425 | K13: 0.8490062 | M13: 3 | N13: 3 | O13: 2 | P13: 4 | Q13: 0.87672823
A14: 01v | C14: 0.7860051 | D14: 0.90884906 | E14: 0.99792707 | F14: 0.8252616 | H14: 0.87612075 | I14: 0.88325991 | J14: 1 | K14: 0.77749295 | M14: 1 | N14: 3 | O14: 1 | P14: 4 | Q14: 0.87951071
A15: 04b | C15: 0.78062862 | D15: 0.93961203 | E15: 0.91286324 | F15: 0.89369116 | H15: 0.8445572 | I15: 0.96603876 | J15: 0.9987975 | K15: 0.93509894 | M15: 3 | N15: 1 | O15: 1 | P15: 1 | Q15: 0.88169876
A16: 02a | C16: 0.78676248 | D16: 0.88446295 | E16: 0.97741719 | F16: 0.88425051 | H16: 0.92616498 | I16: 0.89318814 | J16: 0.98091106 | K16: 0.90666555 | M16: 1 | N16: 4 | O16: 1 | P16: 2 | Q16: 0.88322328
A17: 02b | C17: 0.87331132 | D17: 0.8995235 | E17: 0.84678689 | F17: 0.91449232 | H17: 0.94518746 | I17: 0.96531181 | J17: 0.95747451 | K17: 0.94269629 | M17: 1 | N17: 1 | O17: 2 | P17: 1 | Q17: 0.88352851
A18: 04x | C18: 0.90190898 | D18: 0.95145243 | E18: 0.88551493 | F18: 0.79877546 | H18: 0.95525012 | I18: 0.9713759 | J18: 0.90701749 | K18: 0.89998313 | M18: 1 | N18: 1 | O18: 2 | P18: 3 | Q18: 0.88441295
A19: 01w | C19: 0.76063529 | D19: 0.91695458 | E19: 0.97317321 | F19: 0.90244624 | H19: 0.98449524 | I19: 0.94701987 | J19: 0.97088083 | K19: 0.89795708 | M19: 1 | N19: 1 | O19: 2 | P19: 4 | Q19: 0.88830233
... A24: 03i | C24: 0.79587679 | D24: 0.94966682 | E24: 0.92083477 | F24: 0.90558393 | H24: 0.98244146 | I24: 0.99504059 | J24: 0.96443467 | K24: 0.87878587 | M24: 1 | N24: 1 | O24: 1 | P24: 4 | Q24: 0.89299058
A25: 02z | C25: 0.92034524 | D25: 0.92587531 | E25: 0.80070426 | F25: 0.93467624 | H25: 0.93424448 | I25: 0.99743562 | J25: 0.94199179 | M25: 1 | N25: 1 | O25: 1 | P25: 4 | Q25: 0.89540026
A26: 03y | C26: 0.8383815 | D26: 0.97258543 | E26: 0.87532872 | F26: 0.91498653 | H26: 0.99263349 | I26: 0.99359135 | J26: 0.88848087 | K26: 0.93102539 | M26: 1 | N26: 1 | O26: 2 | P26: 1 | Q26: 0.90032054
A27: 03z | C27: 0.81270907 | D27: 0.95072267 | E27: 0.94903773 | F27: 0.90223353 | H27: 0.85499867 | I27: 0.9523712 | J27: 0.958718 | K27: 0.88140405 | M27: 1 | N27: 1 | O27: 1 | P27: 3 | Q27: 0.90367575
A28: 04s | C28: 0.87586434 | D28: 0.97054704 | E28: 0.93856788 | F28: 0.84976188 | H28: 0.89717466 | I28: 0.97352279 | J28: 0.91735892 | K28: 0.84675554 | M28: 1 | N28: 2 | O28: 2 | P28: 4 | Q28: 0.90868529
A29: 04i | C29: 0.85659173 | D29: 0.95341152 | E29: 0.95558982 | F29: 0.88622275 | H29: 0.97513278 | I29: 0.94436391 | J29: 0.97651634 | K29: 0.78203455 | M29: 1 | N29: 1 | O29: 1 | P29: 4 | Q29: 0.91295395
A30: 03e | C30: 0.89394217 | D30: 0.99586492 | E30: 0.86428661 | F30: 0.90140023 | H30: 0.95821505 | I30: 0.9979085 | J30: 0.89254477 | K30: 0.88871438 | M30: 1 | N30: 1 | O30: 1 | P30: 4 | Q30: 0.91387348
A31: 01c | C31: 0.84420281 | D31: 0.92282361 | E31: 0.99912748 | F31: 0.89145837 | H31: 0.84323637 | I31: 0.93628247 | J31: 0.999357 | K31: 0.78689788 | M31: 4 | N31: 2 | O31: 2 | P31: 4 | Q31: 0.91440307
A32: 000 | C32: 0.88970316 | D32: 0.95042381 | E32: 0.91326402 | F32: 0.90532287 | H32: 0.93215764 | I32: 0.96065737 | J32: 0.94343431 | K32: 0.88080203 | M32: 1 | N32: 1 | O32: 1 | P32: 4 | Q32: 0.91467847
A33: 04q | C33: 0.88271651 | D33: 0.93702523 | E33: 0.93009853 | F33: 0.92475865 | H33: 0.93929724 | I33: 0.9306451 | J33: 0.94875056 | K33: 0.86714758 | M33: 1 | N33: 2 | O33: 1 | P33: 4 | Q33: 0.91864973
A34: 04j | C34: 0.87793385 | D34: 0.97766745 | E34: 0.92668771 | F34: 0.89482917 | H34: 0.9319504 | I34: 0.99424533 | J34: 0.93246968 | K34: 0.79363265 | M34: 2 | N34: 1 | O34: 2 | P34: 4 | Q34: 0.91927955
A35: 01f | C35: 0.81873601 | D35: 0.96748847 | E35: 0.9968254 | F35: 0.90702099 | H35: 0.77342956 | I35: 0.97340181 | J35: 1 | K35: 0.91926937 | M35: 3 | N35: 2 | O35: 1 | P35: 2 | Q35: 0.92251772
A36: 02h | C36: 0.89840983 | D36: 0.95262921 | E36: 0.93781528 | F36: 0.90135436 | H36: 0.93029767 | I36: 0.96663606 | J36: 0.9667912 | K36: 0.909388 | M36: 2 | N36: 2 | O36: 1 | P36: 2 | Q36: 0.92255217
A37: 03d | C37: 0.97013031 | D37: 0.9975137 | E37: 0.83845066 | F37: 0.88654781 | H37: 0.92469831 | I37: 0.99860238 | J37: 0.868262 | K37: 0.7861695 | M37: 2 | N37: 1 | O37: 2 | P37: 4 | Q37: 0.92316062
... A84: 03j | C84: 0.99427612 | D84: 0.98009302 | E84: 0.94526833 | F84: 0.92407103 | H84: 0.99725187 | I84: 0.99913114 | J84: 0.96726217 | K84: 0.9070313 | M84: 1 | N84: 1 | O84: 1 | P84: 1 | Q84: 0.96092712
A85: 01l | C85: 0.9473116 | D85: 0.99072885 | E85: 0.93518116 | F85: 0.97205642 | H85: 0.98693229 | I85: 0.99072188 | J85: 0.95468441 | M85: 1 | N85: 1 | O85: 1 | P85: 4 | Q85: 0.96131951
A86: 04v | C86: 0.99421699 | D86: 0.97827627 | E86: 0.93607889 | F86: 0.94193926 | H86: 0.98551127 | I86: 0.9542565 | J86: 0.93607306 | K86: 0.93303979 | M86: 2 | N86: 2 | O86: 1 | P86: 2 | Q86: 0.96262785
A87: 04l | C87: 0.99704145 | D87: 0.99875152 | E87: 0.92343479 | F87: 0.9315474 | H87: 0.99580597 | I87: 0.9971867 | J87: 0.98379409 | K87: 0.94126246 | M87: 2 | N87: 2 | O87: 1 | P87: 1 | Q87: 0.96269379
A88: 04u | C88: 0.98534647 | D88: 0.98588575 | E88: 0.95391525 | F88: 0.92822741 | H88: 0.98418854 | I88: 0.98759083 | J88: 0.94026586 | K88: 0.91864163 | M88: 1 | N88: 1 | O88: 2 | P88: 2 | Q88: 0.96334372
A89: 01a | C89: 0.95843991 | D89: 0.98810694 | E89: 0.99590293 | F89: 0.91253873 | H89: 0.99294636 | I89: 0.98819124 | J89: 0.99529412 | K89: 0.88426995 | M89: 1 | N89: 2 | O89: 1 | P89: 4 | Q89: 0.96374713
A90: 02v | C90: 0.9815806 | D90: 0.99072283 | E90: 0.91310613 | F90: 0.97128937 | H90: 0.97126902 | I90: 0.99067871 | J90: 0.93108048 | K90: 0.95754835 | M90: 2 | N90: 1 | O90: 2 | P90: 2 | Q90: 0.96417473
...

Sheet tdb2_alerte
J4: LES CAISSES EN ALERTE EN JUILLET 2015
J5: AVANT VALIDATION RNDC
F7: Déclenchement des alertes : | M7: Résultat annuel cumulé non | Q7: Objectif mensuel non atteint et résultats
F8: Délai de traitement <=15 jours | H8: 0.85 | M8: conforme à l'objectif | Q8: en dégradation / mois précédent
F9: Délai de traitement minima sociaux | H9: 0.9 | Q9: Objectif mensuel non atteint mais en
F10: % de visites avec un temps d'attente < 20 minute | H10: 0.85 | M10: Résultat annuel cumulé | Q10: amélioration / au mois précédent
F11: Taux appels traités agents | H11: 0.9 | M11: conforme à l'objectif | Q11: Objectif atteint mais en dégradation /
Q12: au mois précédent
Q13: Objectif atteint et en amélioration / au mois précédent
J15: RESULTATS CUMULES 2015 | P15: Résultat juillet 2015
F16: Classement | G16: Code | I16: Delai de traitement 15 jours | J16: Delai de traitement minima sociaux | K16: Visites<20 minutes | L16: Taux appels traités agents | P16: Délai de traitement 15j | Q16: Minima sociaux | R16: Taux visite 20min | S16: Taux appels traités agents | V16: del | W16: min | X16: vis | Y16: tel | Z16: ind
F17: 103 | G17: 02c | I17: 0.73449245 | J17: 0.7177302 | K17: 0.64834758 | L17: 0.88218284 | P17: 0.82509926 | Q17: 0.6755908 | R17: 0.45687953 | S17: 0.90546084 | V17: 3 | W17: 4 | X17: 4 | Y17: 2 | Z17: 0.74568827
F18: 102 | G18: 04c | I18: 0.79809555 | J18: 0.8529679 | K18: 0.71927025 | L18: 0.89171053 | P18: 0.86505359 | Q18: 0.86267882 | R18: 0.90394089 | S18: 0.89889411 | V18: 1 | W18: 4 | X18: 2 | Y18: 4 | Z18: 0.81551106
F19: 101 | G19: 04t | I19: 0.71941934 | J19: 0.90436416 | K19: 0.78753236 | L19: 0.92625984 | P19: 0.87594945 | Q19: 0.87842178 | R19: 0.95240511 | S19: 0.92370828 | V19: 1 | W19: 4 | X19: 1 | Y19: 1 | Z19: 0.83439392
F20: 100 | G20: 04w | I20: 0.84659499 | J20: 0.96757994 | K20: 0.63024739 | L20: 0.91908502 | P20: 0.98211485 | Q20: 0.98085485 | R20: 0.73437706 | S20: 0.90066815 | V20: 1 | W20: 1 | X20: 3 | Y20: 2 | Z20: 0.84087683
F21: 99 | G21: 01m | I21: 0.66843456 | J21: 0.8886898 | K21: 0.95497513 | L21: 0.85369222 | P21: 0.70606953 | Q21: 0.87860671 | R21: 0.96100253 | S21: 0.83931837 | V21: 3 | W21: 3 | X21: 2 | Y21: 4 | Z21: 0.84144793
F22: 98 | G22: 03a | I22: 0.78749914 | J22: 0.8522813 | K22: 0.8693881 | L22: 0.91403733 | P22: 0.82720068 | Q22: 0.97685873 | R22: 0.94444833 | V22: 3 | W22: 1 | X22: 1 | Y22: 4 | Z22: 0.85580147
F23: 97 | G23: 01x | I23: 0.93457873 | J23: 0.99696729 | K23: 0.6336257 | L23: 0.88817209 | P23: 0.82937976 | Q23: 0.99779943 | R23: 0.53996737 | S23: 0.79030501 | V23: 3 | W23: 1 | X23: 3 | Y23: 4 | Z23: 0.86333595
F24: 96 | G24: 04h | I24: 0.90686476 | J24: 0.92164785 | K24: 0.74266654 | L24: 0.8879083 | P24: 0.89903897 | Q24: 0.92339893 | R24: 0.77682994 | S24: 0.87067801 | V24: 1 | W24: 2 | X24: 4 | Y24: 4 | Z24: 0.86477186
F25: 95 | G25: 04r | I25: 0.77688759 | J25: 0.87605782 | K25: 0.88722656 | L25: 0.9271056 | P25: 0.81199405 | Q25: 0.89158187 | R25: 0.88317967 | S25: 0.90732696 | V25: 3 | W25: 4 | X25: 2 | Y25: 2 | Z25: 0.86681939
F26: 94 | G26: 01h | I26: 0.82096833 | J26: 0.89473579 | K26: 0.87062082 | L26: 0.89581633 | P26: 0.91620048 | Q26: 0.9130033 | R26: 0.85326777 | S26: 0.82453544 | V26: 1 | W26: 2 | X26: 1 | Y26: 1 | Z26: 0.87053532
F27: 93 | G27: 02k | I27: 0.80552693 | J27: 0.89912307 | K27: 0.83853431 | L27: 0.94219504 | P27: 0.81639162 | Q27: 0.92086111 | R27: 0.83936022 | S27: 0.89251075 | V27: 3 | W27: 2 | X27: 4 | Y27: 4 | Z27: 0.87134483
F28: 92 | G28: 04p | I28: 0.73650558 | J28: 0.88853323 | K28: 0.96851311 | L28: 0.91336098 | P28: 0.73470496 | Q28: 0.88103615 | R28: 0.96892425 | S28: 0.8490062 | V28: 3 | W28: 3 | X28: 2 | Y28: 4 | Z28: 0.87672823
F29: 91 | G29: 01v | I29: 0.7860051 | J29: 0.90884906 | K29: 0.99792707 | L29: 0.8252616 | P29: 0.87612075 | Q29: 0.88325991 | R29: 1 | S29: 0.77749295 | V29: 1 | W29: 3 | X29: 1 | Y29: 3 | Z29: 0.87951071
F30: 90 | G30: 04b | I30: 0.78062862 | J30: 0.93961203 | K30: 0.91286324 | L30: 0.89369116 | P30: 0.8445572 | Q30: 0.96603876 | R30: 0.9987975 | S30: 0.93509894 | V30: 3 | W30: 1 | X30: 1 | Y30: 1 | Z30: 0.88169876
F31: 89 | G31: 02a | I31: 0.78676248 | J31: 0.88446295 | K31: 0.97741719 | L31: 0.88425051 | P31: 0.92616498 | Q31: 0.89318814 | R31: 0.98091106 | S31: 0.90666555 | V31: 1 | W31: 4 | X31: 1 | Y31: 1 | Z31: 0.88322328
F32: 88 | G32: 02b | I32: 0.87331132 | J32: 0.8995235 | K32: 0.84678689 | L32: 0.91449232 | P32: 0.94518746 | Q32: 0.96531181 | R32: 0.95747451 | S32: 0.94269629 | V32: 1 | W32: 1 | X32: 2 | Y32: 1 | Z32: 0.88352851
F33: 87 | G33: 04x | I33: 0.90190898 | J33: 0.95145243 | K33: 0.88551493 | L33: 0.79877546 | P33: 0.95525012 | Q33: 0.9713759 | R33: 0.90701749 | S33: 0.89998313 | V33: 1 | W33: 1 | X33: 2 | Y33: 3 | Z33: 0.88441295
F34: 86 | G34: 01w | I34: 0.76063529 | J34: 0.91695458 | K34: 0.97317321 | L34: 0.90244624 | P34: 0.98449524 | Q34: 0.94701987 | R34: 0.97088083 | S34: 0.89795708 | V34: 1 | W34: 1 | X34: 2 | Y34: 3 | Z34: 0.88830233
... F39: 81 | G39: 03i | I39: 0.79587679 | J39: 0.94966682 | K39: 0.92083477 | L39: 0.90558393 | P39: 0.98244146 | Q39: 0.99504059 | R39: 0.96443467 | S39: 0.87878587 | V39: 1 | W39: 1 | X39: 1 | Y39: 3 | Z39: 0.89299058
F40: 80 | G40: 02z | I40: 0.92034524 | J40: 0.92587531 | K40: 0.80070426 | L40: 0.93467624 | P40: 0.93424448 | Q40: 0.99743562 | R40: 0.94199179 | V40: 1 | W40: 1 | X40: 1 | Y40: 3 | Z40: 0.89540026
F41: 79 | G41: 03y | I41: 0.8383815 | J41: 0.97258543 | K41: 0.87532872 | L41: 0.91498653 | P41: 0.99263349 | Q41: 0.99359135 | R41: 0.88848087 | S41: 0.93102539 | V41: 1 | W41: 1 | X41: 2 | Y41: 2 | Z41: 0.90032054
F42: 78 | G42: 03z | I42: 0.81270907 | J42: 0.95072267 | K42: 0.94903773 | L42: 0.90223353 | P42: 0.85499867 | Q42: 0.9523712 | R42: 0.958718 | S42: 0.88140405 | V42: 1 | W42: 1 | X42: 1 | Y42: 4 | Z42: 0.90367575
F43: 77 | G43: 04s | I43: 0.87586434 | J43: 0.97054704 | K43: 0.93856788 | L43: 0.84976188 | P43: 0.89717466 | Q43: 0.97352279 | R43: 0.91735892 | S43: 0.84675554 | V43: 1 | W43: 2 | X43: 2 | Y43: 3 | Z43: 0.90868529
F44: 76 | G44: 04i | I44: 0.85659173 | J44: 0.95341152 | K44: 0.95558982 | L44: 0.88622275 | P44: 0.97513278 | Q44: 0.94436391 | R44: 0.97651634 | S44: 0.78203455 | V44: 1 | W44: 1 | X44: 1 | Y44: 3 | Z44: 0.91295395
F45: 75 | G45: 03e | I45: 0.89394217 | J45: 0.99586492 | K45: 0.86428661 | L45: 0.90140023 | P45: 0.95821505 | Q45: 0.9979085 | R45: 0.89254477 | S45: 0.88871438 | V45: 1 | W45: 1 | X45: 1 | Y45: 3 | Z45: 0.91387348
F46: 74 | G46: 01c | I46: 0.84420281 | J46: 0.92282361 | K46: 0.99912748 | L46: 0.89145837 | P46: 0.84323637 | Q46: 0.93628247 | R46: 0.999357 | S46: 0.78689788 | V46: 4 | W46: 2 | X46: 2 | Y46: 4 | Z46: 0.91440307
F47: 73 | G47: 000 | I47: 0.88970316 | J47: 0.95042381 | K47: 0.91326402 | L47: 0.90532287 | P47: 0.93215764 | Q47: 0.96065737 | R47: 0.94343431 | S47: 0.88080203 | V47: 1 | W47: 1 | X47: 1 | Y47: 3 | Z47: 0.91467847
F48: 72 | G48: 04q | I48: 0.88271651 | J48: 0.93702523 | K48: 0.93009853 | L48: 0.92475865 | P48: 0.93929724 | Q48: 0.9306451 | R48: 0.94875056 | S48: 0.86714758 | V48: 1 | W48: 2 | X48: 1 | Y48: 3 | Z48: 0.91864973
F49: 71 | G49: 04j | I49: 0.87793385 | J49: 0.97766745 | K49: 0.92668771 | L49: 0.89482917 | P49: 0.9319504 | Q49: 0.99424533 | R49: 0.93246968 | S49: 0.79363265 | V49: 2 | W49: 1 | X49: 2 | Y49: 3 | Z49: 0.91927955
...
